TypeError: Invalid comparison between dtype=datetime64[ns] and date
Traceback:
File "/home/runner/workspace/.pythonlibs/lib/python3.11/site-packages/streamlit/runtime/scriptrunner/exec_code.py", line 121, in exec_func_with_error_handling
    result = func()
             ^^^^^^
File "/home/runner/workspace/.pythonlibs/lib/python3.11/site-packages/streamlit/runtime/scriptrunner/script_runner.py", line 591, in code_to_exec
    exec(code, module.__dict__)
File "/home/runner/workspace/pages/1_ðŸ“Š_Site_Dashboard.py", line 442, in <module>
    biomass_fig, biomass_config = graph_generator.create_time_series(
                                  ^^^^^^^^^^^^^^^^^^^^^^^^^^^^^^^^^^^
File "/home/runner/workspace/utils/graph_generator.py", line 176, in create_time_series
    pre_covid = data[data['date'] < covid_start]
                     ^^^^^^^^^^^^^^^^^^^^^^^^^^
File "/home/runner/workspace/.pythonlibs/lib/python3.11/site-packages/pandas/core/ops/common.py", line 76, in new_method
    return method(self, other)
           ^^^^^^^^^^^^^^^^^^^
File "/home/runner/workspace/.pythonlibs/lib/python3.11/site-packages/pandas/core/arraylike.py", line 48, in __lt__
    return self._cmp_method(other, operator.lt)
           ^^^^^^^^^^^^^^^^^^^^^^^^^^^^^^^^^^^^
File "/home/runner/workspace/.pythonlibs/lib/python3.11/site-packages/pandas/core/series.py", line 6119, in _cmp_method
    res_values = ops.comparison_op(lvalues, rvalues, op)
                 ^^^^^^^^^^^^^^^^^^^^^^^^^^^^^^^^^^^^^^^
File "/home/runner/workspace/.pythonlibs/lib/python3.11/site-packages/pandas/core/ops/array_ops.py", line 330, in comparison_op
    res_values = op(lvalues, rvalues)
                 ^^^^^^^^^^^^^^^^^^^^
File "/home/runner/workspace/.pythonlibs/lib/python3.11/site-packages/pandas/core/ops/common.py", line 76, in new_method
    return method(self, other)
           ^^^^^^^^^^^^^^^^^^^
File "/home/runner/workspace/.pythonlibs/lib/python3.11/site-packages/pandas/core/arraylike.py", line 48, in __lt__
    return self._cmp_method(other, operator.lt)
           ^^^^^^^^^^^^^^^^^^^^^^^^^^^^^^^^^^^^
File "/home/runner/workspace/.pythonlibs/lib/python3.11/site-packages/pandas/core/arrays/datetimelike.py", line 985, in _cmp_method
    return invalid_comparison(self, other, op)
           ^^^^^^^^^^^^^^^^^^^^^^^^^^^^^^^^^^^
File "/home/runner/workspace/.pythonlibs/lib/python3.11/site-packages/pandas/core/ops/invalid.py", line 40, in invalid_comparison
    raise TypeError(f"Invalid comparison between dtype={left.dtype} and {typ}")